FEEEE
======================================================================
ERROR: test_invalid (__main__.TestCountLarge)
----------------------------------------------------------------------
Traceback (most recent call last):
  File "/stud/cslec/209/marking/grading/a1/marking_scripts/test_helpers.py", line 161, in _t
    stdout, stderr, returncode = self._run_exec(args=args, input_=input_, timeout=timeout, check=check)
  File "/stud/cslec/209/marking/grading/a1/marking_scripts/test_helpers.py", line 101, in _run_exec
    **kwargs)
  File "/stud/cslec/209/marking/grading/a1/marking_scripts/test_helpers.py", line 496, in _exec
    shell=shell)
  File "/opt/anaconda3/lib/python3.6/subprocess.py", line 707, in __init__
    restore_signals, start_new_session)
  File "/opt/anaconda3/lib/python3.6/subprocess.py", line 1326, in _execute_child
    raise child_exception_type(errno_num, err_msg)
FileNotFoundError: [Errno 2] No such file or directory: './validate_sin'

======================================================================
ERROR: test_too_few_args (__main__.TestCountLarge)
----------------------------------------------------------------------
Traceback (most recent call last):
  File "/stud/cslec/209/marking/grading/a1/marking_scripts/test_helpers.py", line 161, in _t
    stdout, stderr, returncode = self._run_exec(args=args, input_=input_, timeout=timeout, check=check)
  File "/stud/cslec/209/marking/grading/a1/marking_scripts/test_helpers.py", line 101, in _run_exec
    **kwargs)
  File "/stud/cslec/209/marking/grading/a1/marking_scripts/test_helpers.py", line 496, in _exec
    shell=shell)
  File "/opt/anaconda3/lib/python3.6/subprocess.py", line 707, in __init__
    restore_signals, start_new_session)
  File "/opt/anaconda3/lib/python3.6/subprocess.py", line 1326, in _execute_child
    raise child_exception_type(errno_num, err_msg)
FileNotFoundError: [Errno 2] No such file or directory: './validate_sin'

======================================================================
ERROR: test_too_many_args (__main__.TestCountLarge)
----------------------------------------------------------------------
Traceback (most recent call last):
  File "/stud/cslec/209/marking/grading/a1/marking_scripts/test_helpers.py", line 161, in _t
    stdout, stderr, returncode = self._run_exec(args=args, input_=input_, timeout=timeout, check=check)
  File "/stud/cslec/209/marking/grading/a1/marking_scripts/test_helpers.py", line 101, in _run_exec
    **kwargs)
  File "/stud/cslec/209/marking/grading/a1/marking_scripts/test_helpers.py", line 496, in _exec
    shell=shell)
  File "/opt/anaconda3/lib/python3.6/subprocess.py", line 707, in __init__
    restore_signals, start_new_session)
  File "/opt/anaconda3/lib/python3.6/subprocess.py", line 1326, in _execute_child
    raise child_exception_type(errno_num, err_msg)
FileNotFoundError: [Errno 2] No such file or directory: './validate_sin'

======================================================================
ERROR: test_valid (__main__.TestCountLarge)
----------------------------------------------------------------------
Traceback (most recent call last):
  File "/stud/cslec/209/marking/grading/a1/marking_scripts/test_helpers.py", line 161, in _t
    stdout, stderr, returncode = self._run_exec(args=args, input_=input_, timeout=timeout, check=check)
  File "/stud/cslec/209/marking/grading/a1/marking_scripts/test_helpers.py", line 101, in _run_exec
    **kwargs)
  File "/stud/cslec/209/marking/grading/a1/marking_scripts/test_helpers.py", line 496, in _exec
    shell=shell)
  File "/opt/anaconda3/lib/python3.6/subprocess.py", line 707, in __init__
    restore_signals, start_new_session)
  File "/opt/anaconda3/lib/python3.6/subprocess.py", line 1326, in _execute_child
    raise child_exception_type(errno_num, err_msg)
FileNotFoundError: [Errno 2] No such file or directory: './validate_sin'

======================================================================
FAIL: test_compiler_warnings (__main__.TestCountLarge)
----------------------------------------------------------------------
Traceback (most recent call last):
  File "validate_sin_test.py", line 14, in test_compiler_warnings
    self._check_compiler_warnings()
  File "/stud/cslec/209/marking/grading/a1/marking_scripts/test_helpers.py", line 96, in _check_compiler_warnings
    self.assertEqual(self.compile_err, '')
AssertionError: "sin_helpers.o: In function `populate_arr[380 chars] 1\n" != ''
- sin_helpers.o: In function `populate_array':
- sin_helpers.c:(.text+0x0): multiple definition of `populate_array'
- validate_sin.o:validate_sin.c:(.text+0x0): first defined here
- sin_helpers.o: In function `check_sin':
- sin_helpers.c:(.text+0x9e): multiple definition of `check_sin'
- validate_sin.o:validate_sin.c:(.text+0x9e): first defined here
- collect2: error: ld returned 1 exit status
- make: *** [validate_sin] Error 1


----------------------------------------------------------------------
Ran 5 tests in 0.235s

FAILED (failures=1, errors=4)
